{
 "cells": [
  {
   "cell_type": "code",
   "execution_count": 6,
   "metadata": {},
   "outputs": [
    {
     "name": "stdout",
     "output_type": "stream",
     "text": [
      "/home/i4624/vscode/gitclone/SWbootProject_2023-7/2nd_cnn\n",
      "Found 267 images belonging to 1 classes.\n",
      "Found 167 images belonging to 8 classes.\n",
      "Found 167 images belonging to 8 classes.\n"
     ]
    }
   ],
   "source": [
    "import os \n",
    "from keras.preprocessing.image import ImageDataGenerator\n",
    "print(os.getcwd())\n",
    "os.getcwd()\n",
    "\n",
    "# Define directories for your dataset\n",
    "base_dir = './content/mvtec_anomaly_detection/'\n",
    "\n",
    "train_dir = os.path.join(base_dir, 'pill', 'train')\n",
    "validation_dir = os.path.join(base_dir, 'pill', 'test')\n",
    "test_dir = os.path.join(base_dir, 'pill', 'test')\n",
    "\n",
    "\n",
    "# Define image preprocessing and augmentation options\n",
    "train_datagen = ImageDataGenerator(\n",
    "    rescale=1./255,  # Normalize pixel values between 0 and 1\n",
    "    rotation_range=20,\n",
    "    width_shift_range=0.2,\n",
    "    height_shift_range=0.2,\n",
    "    horizontal_flip=True\n",
    ")\n",
    "\n",
    "test_datagen = ImageDataGenerator(rescale=1./255)  # Only rescale for test set\n",
    "\n",
    "# Generate batches of augmented training data\n",
    "train_generator = train_datagen.flow_from_directory(\n",
    "    train_dir,\n",
    "    target_size=(150, 150),  # Resize images to a fixed size\n",
    "    batch_size=32,\n",
    "    class_mode='categorical'  # For classification tasks\n",
    ")\n",
    "\n",
    "# Generate batches of validation data\n",
    "validation_generator = test_datagen.flow_from_directory(\n",
    "    validation_dir,\n",
    "    target_size=(150, 150),\n",
    "    batch_size=32,\n",
    "    class_mode='categorical'\n",
    ")\n",
    "\n",
    "# Generate batches of test data\n",
    "test_generator = test_datagen.flow_from_directory(\n",
    "    test_dir,\n",
    "    target_size=(150, 150),\n",
    "    batch_size=32,\n",
    "    class_mode='categorical'\n",
    ")\n"
   ]
  },
  {
   "cell_type": "code",
   "execution_count": 9,
   "metadata": {},
   "outputs": [
    {
     "name": "stdout",
     "output_type": "stream",
     "text": [
      "Epoch 1/20\n",
      "9/9 [==============================] - ETA: 0s - loss: 23.4042 - accuracy: 0.6067"
     ]
    },
    {
     "ename": "InvalidArgumentError",
     "evalue": "Graph execution error:\n\nDetected at node 'categorical_crossentropy/softmax_cross_entropy_with_logits' defined at (most recent call last):\n    File \"/usr/lib/python3.10/runpy.py\", line 196, in _run_module_as_main\n      return _run_code(code, main_globals, None,\n    File \"/usr/lib/python3.10/runpy.py\", line 86, in _run_code\n      exec(code, run_globals)\n    File \"/home/i4624/.local/lib/python3.10/site-packages/ipykernel_launcher.py\", line 17, in <module>\n      app.launch_new_instance()\n    File \"/home/i4624/.local/lib/python3.10/site-packages/traitlets/config/application.py\", line 1043, in launch_instance\n      app.start()\n    File \"/home/i4624/.local/lib/python3.10/site-packages/ipykernel/kernelapp.py\", line 728, in start\n      self.io_loop.start()\n    File \"/home/i4624/.local/lib/python3.10/site-packages/tornado/platform/asyncio.py\", line 195, in start\n      self.asyncio_loop.run_forever()\n    File \"/usr/lib/python3.10/asyncio/base_events.py\", line 600, in run_forever\n      self._run_once()\n    File \"/usr/lib/python3.10/asyncio/base_events.py\", line 1896, in _run_once\n      handle._run()\n    File \"/usr/lib/python3.10/asyncio/events.py\", line 80, in _run\n      self._context.run(self._callback, *self._args)\n    File \"/home/i4624/.local/lib/python3.10/site-packages/ipykernel/kernelbase.py\", line 516, in dispatch_queue\n      await self.process_one()\n    File \"/home/i4624/.local/lib/python3.10/site-packages/ipykernel/kernelbase.py\", line 505, in process_one\n      await dispatch(*args)\n    File \"/home/i4624/.local/lib/python3.10/site-packages/ipykernel/kernelbase.py\", line 412, in dispatch_shell\n      await result\n    File \"/home/i4624/.local/lib/python3.10/site-packages/ipykernel/kernelbase.py\", line 740, in execute_request\n      reply_content = await reply_content\n    File \"/home/i4624/.local/lib/python3.10/site-packages/ipykernel/ipkernel.py\", line 422, in do_execute\n      res = shell.run_cell(\n    File \"/home/i4624/.local/lib/python3.10/site-packages/ipykernel/zmqshell.py\", line 540, in run_cell\n      return super().run_cell(*args, **kwargs)\n    File \"/home/i4624/.local/lib/python3.10/site-packages/IPython/core/interactiveshell.py\", line 3009, in run_cell\n      result = self._run_cell(\n    File \"/home/i4624/.local/lib/python3.10/site-packages/IPython/core/interactiveshell.py\", line 3064, in _run_cell\n      result = runner(coro)\n    File \"/home/i4624/.local/lib/python3.10/site-packages/IPython/core/async_helpers.py\", line 129, in _pseudo_sync_runner\n      coro.send(None)\n    File \"/home/i4624/.local/lib/python3.10/site-packages/IPython/core/interactiveshell.py\", line 3269, in run_cell_async\n      has_raised = await self.run_ast_nodes(code_ast.body, cell_name,\n    File \"/home/i4624/.local/lib/python3.10/site-packages/IPython/core/interactiveshell.py\", line 3448, in run_ast_nodes\n      if await self.run_code(code, result, async_=asy):\n    File \"/home/i4624/.local/lib/python3.10/site-packages/IPython/core/interactiveshell.py\", line 3508, in run_code\n      exec(code_obj, self.user_global_ns, self.user_ns)\n    File \"/tmp/ipykernel_1757033/3970908299.py\", line 27, in <module>\n      history = model.fit(\n    File \"/home/i4624/.local/lib/python3.10/site-packages/keras/src/utils/traceback_utils.py\", line 65, in error_handler\n      return fn(*args, **kwargs)\n    File \"/home/i4624/.local/lib/python3.10/site-packages/keras/src/engine/training.py\", line 1791, in fit\n      val_logs = self.evaluate(\n    File \"/home/i4624/.local/lib/python3.10/site-packages/keras/src/utils/traceback_utils.py\", line 65, in error_handler\n      return fn(*args, **kwargs)\n    File \"/home/i4624/.local/lib/python3.10/site-packages/keras/src/engine/training.py\", line 2200, in evaluate\n      logs = test_function_runner.run_step(\n    File \"/home/i4624/.local/lib/python3.10/site-packages/keras/src/engine/training.py\", line 4000, in run_step\n      tmp_logs = self._function(dataset_or_iterator)\n    File \"/home/i4624/.local/lib/python3.10/site-packages/keras/src/engine/training.py\", line 1972, in test_function\n      return step_function(self, iterator)\n    File \"/home/i4624/.local/lib/python3.10/site-packages/keras/src/engine/training.py\", line 1956, in step_function\n      outputs = model.distribute_strategy.run(run_step, args=(data,))\n    File \"/home/i4624/.local/lib/python3.10/site-packages/keras/src/engine/training.py\", line 1944, in run_step\n      outputs = model.test_step(data)\n    File \"/home/i4624/.local/lib/python3.10/site-packages/keras/src/engine/training.py\", line 1852, in test_step\n      self.compute_loss(x, y, y_pred, sample_weight)\n    File \"/home/i4624/.local/lib/python3.10/site-packages/keras/src/engine/training.py\", line 1139, in compute_loss\n      return self.compiled_loss(\n    File \"/home/i4624/.local/lib/python3.10/site-packages/keras/src/engine/compile_utils.py\", line 265, in __call__\n      loss_value = loss_obj(y_t, y_p, sample_weight=sw)\n    File \"/home/i4624/.local/lib/python3.10/site-packages/keras/src/losses.py\", line 142, in __call__\n      losses = call_fn(y_true, y_pred)\n    File \"/home/i4624/.local/lib/python3.10/site-packages/keras/src/losses.py\", line 268, in call\n      return ag_fn(y_true, y_pred, **self._fn_kwargs)\n    File \"/home/i4624/.local/lib/python3.10/site-packages/keras/src/losses.py\", line 2122, in categorical_crossentropy\n      return backend.categorical_crossentropy(\n    File \"/home/i4624/.local/lib/python3.10/site-packages/keras/src/backend.py\", line 5566, in categorical_crossentropy\n      return tf.nn.softmax_cross_entropy_with_logits(\nNode: 'categorical_crossentropy/softmax_cross_entropy_with_logits'\nlogits and labels must be broadcastable: logits_size=[32,2] labels_size=[32,8]\n\t [[{{node categorical_crossentropy/softmax_cross_entropy_with_logits}}]] [Op:__inference_test_function_5397]",
     "output_type": "error",
     "traceback": [
      "\u001b[0;31m---------------------------------------------------------------------------\u001b[0m",
      "\u001b[0;31mInvalidArgumentError\u001b[0m                      Traceback (most recent call last)",
      "Cell \u001b[0;32mIn[9], line 27\u001b[0m\n\u001b[1;32m     24\u001b[0m model\u001b[39m.\u001b[39mcompile(optimizer\u001b[39m=\u001b[39m\u001b[39m'\u001b[39m\u001b[39madam\u001b[39m\u001b[39m'\u001b[39m, loss\u001b[39m=\u001b[39m\u001b[39m'\u001b[39m\u001b[39mcategorical_crossentropy\u001b[39m\u001b[39m'\u001b[39m, metrics\u001b[39m=\u001b[39m[\u001b[39m'\u001b[39m\u001b[39maccuracy\u001b[39m\u001b[39m'\u001b[39m])\n\u001b[1;32m     26\u001b[0m \u001b[39m# Train the model\u001b[39;00m\n\u001b[0;32m---> 27\u001b[0m history \u001b[39m=\u001b[39m model\u001b[39m.\u001b[39;49mfit(\n\u001b[1;32m     28\u001b[0m     train_generator,\n\u001b[1;32m     29\u001b[0m     steps_per_epoch\u001b[39m=\u001b[39;49m\u001b[39mlen\u001b[39;49m(train_generator),\n\u001b[1;32m     30\u001b[0m     epochs\u001b[39m=\u001b[39;49m\u001b[39m20\u001b[39;49m,\n\u001b[1;32m     31\u001b[0m     validation_data\u001b[39m=\u001b[39;49mvalidation_generator,\n\u001b[1;32m     32\u001b[0m     validation_steps\u001b[39m=\u001b[39;49m\u001b[39mlen\u001b[39;49m(validation_generator)\n\u001b[1;32m     33\u001b[0m )\n",
      "File \u001b[0;32m~/.local/lib/python3.10/site-packages/keras/src/utils/traceback_utils.py:70\u001b[0m, in \u001b[0;36mfilter_traceback.<locals>.error_handler\u001b[0;34m(*args, **kwargs)\u001b[0m\n\u001b[1;32m     67\u001b[0m     filtered_tb \u001b[39m=\u001b[39m _process_traceback_frames(e\u001b[39m.\u001b[39m__traceback__)\n\u001b[1;32m     68\u001b[0m     \u001b[39m# To get the full stack trace, call:\u001b[39;00m\n\u001b[1;32m     69\u001b[0m     \u001b[39m# `tf.debugging.disable_traceback_filtering()`\u001b[39;00m\n\u001b[0;32m---> 70\u001b[0m     \u001b[39mraise\u001b[39;00m e\u001b[39m.\u001b[39mwith_traceback(filtered_tb) \u001b[39mfrom\u001b[39;00m \u001b[39mNone\u001b[39;00m\n\u001b[1;32m     71\u001b[0m \u001b[39mfinally\u001b[39;00m:\n\u001b[1;32m     72\u001b[0m     \u001b[39mdel\u001b[39;00m filtered_tb\n",
      "File \u001b[0;32m~/.local/lib/python3.10/site-packages/tensorflow/python/eager/execute.py:53\u001b[0m, in \u001b[0;36mquick_execute\u001b[0;34m(op_name, num_outputs, inputs, attrs, ctx, name)\u001b[0m\n\u001b[1;32m     51\u001b[0m \u001b[39mtry\u001b[39;00m:\n\u001b[1;32m     52\u001b[0m   ctx\u001b[39m.\u001b[39mensure_initialized()\n\u001b[0;32m---> 53\u001b[0m   tensors \u001b[39m=\u001b[39m pywrap_tfe\u001b[39m.\u001b[39mTFE_Py_Execute(ctx\u001b[39m.\u001b[39m_handle, device_name, op_name,\n\u001b[1;32m     54\u001b[0m                                       inputs, attrs, num_outputs)\n\u001b[1;32m     55\u001b[0m \u001b[39mexcept\u001b[39;00m core\u001b[39m.\u001b[39m_NotOkStatusException \u001b[39mas\u001b[39;00m e:\n\u001b[1;32m     56\u001b[0m   \u001b[39mif\u001b[39;00m name \u001b[39mis\u001b[39;00m \u001b[39mnot\u001b[39;00m \u001b[39mNone\u001b[39;00m:\n",
      "\u001b[0;31mInvalidArgumentError\u001b[0m: Graph execution error:\n\nDetected at node 'categorical_crossentropy/softmax_cross_entropy_with_logits' defined at (most recent call last):\n    File \"/usr/lib/python3.10/runpy.py\", line 196, in _run_module_as_main\n      return _run_code(code, main_globals, None,\n    File \"/usr/lib/python3.10/runpy.py\", line 86, in _run_code\n      exec(code, run_globals)\n    File \"/home/i4624/.local/lib/python3.10/site-packages/ipykernel_launcher.py\", line 17, in <module>\n      app.launch_new_instance()\n    File \"/home/i4624/.local/lib/python3.10/site-packages/traitlets/config/application.py\", line 1043, in launch_instance\n      app.start()\n    File \"/home/i4624/.local/lib/python3.10/site-packages/ipykernel/kernelapp.py\", line 728, in start\n      self.io_loop.start()\n    File \"/home/i4624/.local/lib/python3.10/site-packages/tornado/platform/asyncio.py\", line 195, in start\n      self.asyncio_loop.run_forever()\n    File \"/usr/lib/python3.10/asyncio/base_events.py\", line 600, in run_forever\n      self._run_once()\n    File \"/usr/lib/python3.10/asyncio/base_events.py\", line 1896, in _run_once\n      handle._run()\n    File \"/usr/lib/python3.10/asyncio/events.py\", line 80, in _run\n      self._context.run(self._callback, *self._args)\n    File \"/home/i4624/.local/lib/python3.10/site-packages/ipykernel/kernelbase.py\", line 516, in dispatch_queue\n      await self.process_one()\n    File \"/home/i4624/.local/lib/python3.10/site-packages/ipykernel/kernelbase.py\", line 505, in process_one\n      await dispatch(*args)\n    File \"/home/i4624/.local/lib/python3.10/site-packages/ipykernel/kernelbase.py\", line 412, in dispatch_shell\n      await result\n    File \"/home/i4624/.local/lib/python3.10/site-packages/ipykernel/kernelbase.py\", line 740, in execute_request\n      reply_content = await reply_content\n    File \"/home/i4624/.local/lib/python3.10/site-packages/ipykernel/ipkernel.py\", line 422, in do_execute\n      res = shell.run_cell(\n    File \"/home/i4624/.local/lib/python3.10/site-packages/ipykernel/zmqshell.py\", line 540, in run_cell\n      return super().run_cell(*args, **kwargs)\n    File \"/home/i4624/.local/lib/python3.10/site-packages/IPython/core/interactiveshell.py\", line 3009, in run_cell\n      result = self._run_cell(\n    File \"/home/i4624/.local/lib/python3.10/site-packages/IPython/core/interactiveshell.py\", line 3064, in _run_cell\n      result = runner(coro)\n    File \"/home/i4624/.local/lib/python3.10/site-packages/IPython/core/async_helpers.py\", line 129, in _pseudo_sync_runner\n      coro.send(None)\n    File \"/home/i4624/.local/lib/python3.10/site-packages/IPython/core/interactiveshell.py\", line 3269, in run_cell_async\n      has_raised = await self.run_ast_nodes(code_ast.body, cell_name,\n    File \"/home/i4624/.local/lib/python3.10/site-packages/IPython/core/interactiveshell.py\", line 3448, in run_ast_nodes\n      if await self.run_code(code, result, async_=asy):\n    File \"/home/i4624/.local/lib/python3.10/site-packages/IPython/core/interactiveshell.py\", line 3508, in run_code\n      exec(code_obj, self.user_global_ns, self.user_ns)\n    File \"/tmp/ipykernel_1757033/3970908299.py\", line 27, in <module>\n      history = model.fit(\n    File \"/home/i4624/.local/lib/python3.10/site-packages/keras/src/utils/traceback_utils.py\", line 65, in error_handler\n      return fn(*args, **kwargs)\n    File \"/home/i4624/.local/lib/python3.10/site-packages/keras/src/engine/training.py\", line 1791, in fit\n      val_logs = self.evaluate(\n    File \"/home/i4624/.local/lib/python3.10/site-packages/keras/src/utils/traceback_utils.py\", line 65, in error_handler\n      return fn(*args, **kwargs)\n    File \"/home/i4624/.local/lib/python3.10/site-packages/keras/src/engine/training.py\", line 2200, in evaluate\n      logs = test_function_runner.run_step(\n    File \"/home/i4624/.local/lib/python3.10/site-packages/keras/src/engine/training.py\", line 4000, in run_step\n      tmp_logs = self._function(dataset_or_iterator)\n    File \"/home/i4624/.local/lib/python3.10/site-packages/keras/src/engine/training.py\", line 1972, in test_function\n      return step_function(self, iterator)\n    File \"/home/i4624/.local/lib/python3.10/site-packages/keras/src/engine/training.py\", line 1956, in step_function\n      outputs = model.distribute_strategy.run(run_step, args=(data,))\n    File \"/home/i4624/.local/lib/python3.10/site-packages/keras/src/engine/training.py\", line 1944, in run_step\n      outputs = model.test_step(data)\n    File \"/home/i4624/.local/lib/python3.10/site-packages/keras/src/engine/training.py\", line 1852, in test_step\n      self.compute_loss(x, y, y_pred, sample_weight)\n    File \"/home/i4624/.local/lib/python3.10/site-packages/keras/src/engine/training.py\", line 1139, in compute_loss\n      return self.compiled_loss(\n    File \"/home/i4624/.local/lib/python3.10/site-packages/keras/src/engine/compile_utils.py\", line 265, in __call__\n      loss_value = loss_obj(y_t, y_p, sample_weight=sw)\n    File \"/home/i4624/.local/lib/python3.10/site-packages/keras/src/losses.py\", line 142, in __call__\n      losses = call_fn(y_true, y_pred)\n    File \"/home/i4624/.local/lib/python3.10/site-packages/keras/src/losses.py\", line 268, in call\n      return ag_fn(y_true, y_pred, **self._fn_kwargs)\n    File \"/home/i4624/.local/lib/python3.10/site-packages/keras/src/losses.py\", line 2122, in categorical_crossentropy\n      return backend.categorical_crossentropy(\n    File \"/home/i4624/.local/lib/python3.10/site-packages/keras/src/backend.py\", line 5566, in categorical_crossentropy\n      return tf.nn.softmax_cross_entropy_with_logits(\nNode: 'categorical_crossentropy/softmax_cross_entropy_with_logits'\nlogits and labels must be broadcastable: logits_size=[32,2] labels_size=[32,8]\n\t [[{{node categorical_crossentropy/softmax_cross_entropy_with_logits}}]] [Op:__inference_test_function_5397]"
     ]
    }
   ],
   "source": [
    "from keras.models import Sequential\n",
    "from keras.layers import Conv2D, MaxPooling2D, Flatten, Dense\n",
    "\n",
    "# Create a sequential model\n",
    "model = Sequential()\n",
    "\n",
    "# Add convolutional layers\n",
    "model.add(Conv2D(64, (3, 3), activation='relu', input_shape=(150, 150, 3)))\n",
    "model.add(MaxPooling2D((2, 2)))\n",
    "model.add(Conv2D(128, (3, 3), activation='relu'))\n",
    "model.add(MaxPooling2D((2, 2)))\n",
    "model.add(Conv2D(256, (3, 3), activation='relu'))\n",
    "model.add(MaxPooling2D((2, 2)))\n",
    "\n",
    "# Flatten the feature maps\n",
    "model.add(Flatten())\n",
    "\n",
    "# Add fully connected layers\n",
    "model.add(Dense(128, activation='relu'))\n",
    "model.add(Dense(64, activation='relu'))\n",
    "model.add(Dense(2, activation='softmax'))  # Assuming 2 classes (good and defect)\n",
    "\n",
    "# Compile the model\n",
    "model.compile(optimizer='adam', loss='categorical_crossentropy', metrics=['accuracy'])\n",
    "\n",
    "# Train the model\n",
    "history = model.fit(\n",
    "    train_generator,\n",
    "    steps_per_epoch=len(train_generator),\n",
    "    epochs=20,\n",
    "    validation_data=validation_generator,\n",
    "    validation_steps=len(validation_generator)\n",
    ")\n"
   ]
  }
 ],
 "metadata": {
  "kernelspec": {
   "display_name": "Python 3",
   "language": "python",
   "name": "python3"
  },
  "language_info": {
   "codemirror_mode": {
    "name": "ipython",
    "version": 3
   },
   "file_extension": ".py",
   "mimetype": "text/x-python",
   "name": "python",
   "nbconvert_exporter": "python",
   "pygments_lexer": "ipython3",
   "version": "3.10.6"
  },
  "orig_nbformat": 4
 },
 "nbformat": 4,
 "nbformat_minor": 2
}
